<mujoco model="robotiq_2f_140">
    <compiler angle="radian" meshdir="mesh/gripper" autolimits="true"/>


    <option cone="elliptic" impratio="10"/>

    <asset>
        <material name="gray" rgba="0.1 0.1 0.1 1"/>
        <material name="light_gray" rgba="0.792156862745098 0.819607843137255 0.933333333333333 1"/>
        <material name="white" rgba="0.9 0.9 0.9 1"/>
        
        <mesh name="base_link" file="collision/robotiq_arg2f_base_link.stl"/>
        <mesh name="outer_knuckle" file="collision/robotiq_arg2f_140_outer_knuckle.stl"/>
        <mesh name="outer_finger" file="collision/robotiq_arg2f_140_outer_finger.stl"/>
        <mesh name="inner_finger" file="collision/robotiq_arg2f_140_inner_finger.stl"/>
        <mesh name="inner_knuckle" file="collision/robotiq_arg2f_140_inner_knuckle.stl"/>
    </asset>

    <default>
        <default class="2f140">
            <joint limited="true" damping="0.1" armature="0.001"/>
            
            <default class="visual">
                <geom type="mesh" contype="0" conaffinity="0" group="2"/>
            </default>
            <default class="collision">
                <geom type="mesh" group="3"/>
            </default>
        </default>
    </default>

    <worldbody>    
        <body name="robotiq_arg2f_base_link">
            <inertial pos="8.625e-08 -4.6583e-06 0.03145" mass="0.22652" fullinertia="0.00020005 0.00017832 0.00013478 -4.2442e-10 -2.9069e-10 -3.4402e-08"/>
            <geom class="visual" type="mesh" mesh="base_link" material="gray"/>
            <geom class="collision" type="mesh" mesh="base_link"/>

            <!-- Left finger mechanism -->
            <body name="left_outer_knuckle" pos="0 -0.030601 0.054905" euler="2.29579632679 0 0">
                <inertial pos="-0.0002 0.0199435877845359 0.0292245259211331" mass="0.00853198276973456" fullinertia="2.89328108496468e-06 1.86719750325683e-06 1.21905238907251e-06 -1.57935047237397e-19 -1.93980378593255e-19 -1.21858577871576e-06"/>
                <joint name="finger_joint" axis="-1 0 0" range="0 0.7"/>
                <geom class="visual" type="mesh" mesh="outer_knuckle" material="light_gray"/>
                <geom class="collision" type="mesh" mesh="outer_knuckle"/>

                <body name="left_outer_finger" pos="0 0.01821998610742 0.0260018192872234">
                    <inertial pos="0.00030115855001899 0.0373907951953854 -0.0208027427000385" mass="0.022614240507152" fullinertia="1.52518312458174e-05 6.17694243867776e-06 1.16494917907219e-05 9.76583423954399e-10 -5.43838577022588e-10 6.78636130740228e-06"/>
                    <geom class="visual" type="mesh" mesh="outer_finger" material="gray"/>
                    <geom class="collision" type="mesh" mesh="outer_finger"/>

                    <body name="left_inner_finger" pos="0 0.0817554015893473 -0.0282203446692936" euler="-0.725 0 0">
                        <inertial pos="0.000299999999999317 0.0160078233491243 -0.0136945669206257" mass="0.0104003125914103" fullinertia="2.71909453810972e-06 7.69100314106116e-07 2.30315190420171e-06 1.35402465472579e-21 -7.1817349065269e-22 6.74715432769696e-07"/>
                        <joint name="left_inner_finger_joint" axis="1 0 0" range="-0.8757 0.8757"/>
                        <geom class="visual" type="mesh" mesh="inner_finger" material="gray"/>
                        <geom class="collision" type="mesh" mesh="inner_finger"/>

                        <body name="left_inner_finger_pad" pos="0 0.0457554015893473 -0.0272203446692936">
                            <geom type="box" size="0.0135 0.0325 0.00375" material="white" friction="0.7"/>
                        </body>
                    </body>
                </body>
            </body>

            <body name="left_inner_knuckle" pos="0 -0.0127 0.06142" euler="2.29579632679 0 0">
                <inertial pos="0.000123011831763771 0.0507850843201817 0.00103968640075166" mass="0.0271177346495152" fullinertia="2.61910379223783e-05 2.8270243746167e-06 2.83695868220296e-05 -2.43616858946494e-07 -6.37789906117123e-09 -5.37200748039765e-07"/>
                <joint name="left_inner_knuckle_joint" axis="1 0 0" range="-0.8757 0.8757"/>
                <geom class="visual" type="mesh" mesh="inner_knuckle" material="gray"/>
                <geom class="collision" type="mesh" mesh="inner_knuckle"/>
            </body>

            <!-- Right finger mechanism -->
            <body name="right_outer_knuckle" pos="0 0.030601 0.054905" euler="-2.29579632679 0 3.14">
                <inertial pos="-0.0002 0.0199435877845359 0.0292245259211331" mass="0.00853198276973456" fullinertia="2.89328108496468e-06 1.86719750325683e-06 1.21905238907251e-06 -1.57935047237397e-19 -1.93980378593255e-19 -1.21858577871576e-06"/>
                <joint name="right_outer_knuckle_joint" axis="1 0 0" range="-0.8757 0.8757"/>
                <geom class="visual" type="mesh" mesh="outer_knuckle" material="light_gray"/>
                <geom class="collision" type="mesh" mesh="outer_knuckle"/>

                <body name="right_outer_finger" pos="0 0.01821998610742 0.0260018192872234">
                    <inertial pos="0.00030115855001899 0.0373907951953854 -0.0208027427000385" mass="0.022614240507152" fullinertia="1.52518312458174e-05 6.17694243867776e-06 1.16494917907219e-05 9.76583423954399e-10 -5.43838577022588e-10 6.78636130740228e-06"/>
                    <geom class="visual" type="mesh" mesh="outer_finger" material="gray"/>
                    <geom class="collision" type="mesh" mesh="outer_finger"/>

                    <body name="right_inner_finger" pos="0 0.0817554015893473 -0.0282203446692936" euler="-0.725 0 0">
                        <inertial pos="0.000299999999999317 0.0160078233491243 -0.0136945669206257" mass="0.0104003125914103" fullinertia="2.71909453810972e-06 7.69100314106116e-07 2.30315190420171e-06 1.35402465472579e-21 -7.1817349065269e-22 6.74715432769696e-07"/>
                        <joint name="right_inner_finger_joint" axis="1 0 0" range="-0.8757 0.8757"/>
                        <geom class="visual" type="mesh" mesh="inner_finger" material="gray"/>
                        <geom class="collision" type="mesh" mesh="inner_finger"/>

                        <body name="right_inner_finger_pad" pos="0 0.0457554015893473 -0.0272203446692936">
                            <geom type="box" size="0.0135 0.0325 0.00375" material="white" friction="0.7"/>
                        </body>
                    </body>
                </body>
            </body>

            <body name="right_inner_knuckle" pos="0 0.0127 0.06142" euler="-2.29579632679 0 3.14159265359">
                <inertial pos="0.000123011831763771 0.0507850843201817 0.00103968640075166" mass="0.0271177346495152" fullinertia="2.61910379223783e-05 2.8270243746167e-06 2.83695868220296e-05 -2.43616858946494e-07 -6.37789906117123e-09 -5.37200748039765e-07"/>
                <joint name="right_inner_knuckle_joint" axis="1 0 0" range="-0.8757 0.8757"/>
                <geom class="visual" type="mesh" mesh="inner_knuckle" material="gray"/>
                <geom class="collision" type="mesh" mesh="inner_knuckle"/>
            </body>

            <site name="grasp_site" pos="0 0 0.2" size="0.01 0.01 0.01"/>
        </body>
    </worldbody>

    <equality>
        <joint joint1="finger_joint" joint2="right_outer_knuckle_joint" polycoef="0 -1 0 0 0"/>
        <joint joint1="finger_joint" joint2="left_inner_knuckle_joint" polycoef="0 -1 0 0 0"/>
        <joint joint1="finger_joint" joint2="right_inner_knuckle_joint" polycoef="0 -1 0 0 0"/>
        <joint joint1="finger_joint" joint2="left_inner_finger_joint" polycoef="0 1 0 0 0"/>
        <joint joint1="finger_joint" joint2="right_inner_finger_joint" polycoef="0 1 0 0 0"/>
    </equality>

    <actuator>
        <position name="fingers_actuator" joint="finger_joint" ctrlrange="0 0.7" kp="30"/>
    </actuator>
</mujoco>